[2024-06-15 02:42:00] ERROR [django.request:225] Internal Server Error: /api/events/
Traceback (most recent call last):
  File "D:\Bhangaar\.venv\lib\site-packages\django\utils\dateparse.py", line 116, in parse_datetime
    return datetime.datetime.fromisoformat(value)
ValueError: Invalid isoformat string: '2021-06-31T21:00:00Z'

During handling of the above exception, another exception occurred:

Traceback (most recent call last):
  File "D:\Bhangaar\.venv\lib\site-packages\django\db\models\fields\__init__.py", line 1360, in to_python
    parsed = parse_datetime(value)
  File "D:\Bhangaar\.venv\lib\site-packages\django\utils\dateparse.py", line 131, in parse_datetime
    return datetime.datetime(**kw, tzinfo=tzinfo)
ValueError: day is out of range for month

During handling of the above exception, another exception occurred:

Traceback (most recent call last):
  File "D:\Bhangaar\.venv\lib\site-packages\django\core\handlers\exception.py", line 47, in inner
    response = get_response(request)
  File "D:\Bhangaar\.venv\lib\site-packages\django\core\handlers\base.py", line 181, in _get_response
    response = wrapped_callback(request, *callback_args, **callback_kwargs)
  File "D:\Bhangaar\.venv\lib\site-packages\django\views\decorators\csrf.py", line 54, in wrapped_view
    return view_func(*args, **kwargs)
  File "D:\Bhangaar\.venv\lib\site-packages\django\views\generic\base.py", line 69, in view
    return self.dispatch(request, *args, **kwargs)
  File "D:\Bhangaar\.venv\lib\site-packages\rest_framework\views.py", line 509, in dispatch
    response = self.handle_exception(exc)
  File "D:\Bhangaar\.venv\lib\site-packages\rest_framework\views.py", line 469, in handle_exception
    self.raise_uncaught_exception(exc)
  File "D:\Bhangaar\.venv\lib\site-packages\rest_framework\views.py", line 480, in raise_uncaught_exception
    raise exc
  File "D:\Bhangaar\.venv\lib\site-packages\rest_framework\views.py", line 506, in dispatch
    response = handler(request, *args, **kwargs)
  File "D:\Bhangaar\EventsMarketPlace\events\views.py", line 41, in get
    events = Event.objects.in_datetime_range(starts_at, ends_at)
  File "D:\Bhangaar\.venv\lib\site-packages\django\db\models\manager.py", line 85, in manager_method
    return getattr(self.get_queryset(), name)(*args, **kwargs)
  File "D:\Bhangaar\EventsMarketPlace\events\models.py", line 13, in in_datetime_range
    return self.filter(
  File "D:\Bhangaar\.venv\lib\site-packages\django\db\models\query.py", line 974, in filter
    return self._filter_or_exclude(False, args, kwargs)
  File "D:\Bhangaar\.venv\lib\site-packages\django\db\models\query.py", line 992, in _filter_or_exclude
    clone._filter_or_exclude_inplace(negate, args, kwargs)
  File "D:\Bhangaar\.venv\lib\site-packages\django\db\models\query.py", line 999, in _filter_or_exclude_inplace
    self._query.add_q(Q(*args, **kwargs))
  File "D:\Bhangaar\.venv\lib\site-packages\django\db\models\sql\query.py", line 1375, in add_q
    clause, _ = self._add_q(q_object, self.used_aliases)
  File "D:\Bhangaar\.venv\lib\site-packages\django\db\models\sql\query.py", line 1396, in _add_q
    child_clause, needed_inner = self.build_filter(
  File "D:\Bhangaar\.venv\lib\site-packages\django\db\models\sql\query.py", line 1252, in build_filter
    return self._add_q(
  File "D:\Bhangaar\.venv\lib\site-packages\django\db\models\sql\query.py", line 1396, in _add_q
    child_clause, needed_inner = self.build_filter(
  File "D:\Bhangaar\.venv\lib\site-packages\django\db\models\sql\query.py", line 1329, in build_filter
    condition = self.build_lookup(lookups, col, value)
  File "D:\Bhangaar\.venv\lib\site-packages\django\db\models\sql\query.py", line 1180, in build_lookup
    lookup = lookup_class(lhs, rhs)
  File "D:\Bhangaar\.venv\lib\site-packages\django\db\models\lookups.py", line 22, in __init__
    self.rhs = self.get_prep_lookup()
  File "D:\Bhangaar\.venv\lib\site-packages\django\db\models\lookups.py", line 79, in get_prep_lookup
    return self.lhs.output_field.get_prep_value(self.rhs)
  File "D:\Bhangaar\.venv\lib\site-packages\django\db\models\fields\__init__.py", line 1399, in get_prep_value
    value = super().get_prep_value(value)
  File "D:\Bhangaar\.venv\lib\site-packages\django\db\models\fields\__init__.py", line 1288, in get_prep_value
    return self.to_python(value)
  File "D:\Bhangaar\.venv\lib\site-packages\django\db\models\fields\__init__.py", line 1364, in to_python
    raise exceptions.ValidationError(
django.core.exceptions.ValidationError: ['“2021-06-31T21:00:00Z” value has the correct format (YYYY-MM-DD HH:MM[:ss[.uuuuuu]][TZ]) but it is an invalid date/time.']
[2024-06-15 02:43:06] ERROR [django.request:225] Internal Server Error: /api/events/
Traceback (most recent call last):
  File "D:\Bhangaar\.venv\lib\site-packages\django\utils\dateparse.py", line 116, in parse_datetime
    return datetime.datetime.fromisoformat(value)
ValueError: Invalid isoformat string: '2021-06-31T21:00:00Z'

During handling of the above exception, another exception occurred:

Traceback (most recent call last):
  File "D:\Bhangaar\.venv\lib\site-packages\django\db\models\fields\__init__.py", line 1360, in to_python
    parsed = parse_datetime(value)
  File "D:\Bhangaar\.venv\lib\site-packages\django\utils\dateparse.py", line 131, in parse_datetime
    return datetime.datetime(**kw, tzinfo=tzinfo)
ValueError: day is out of range for month

During handling of the above exception, another exception occurred:

Traceback (most recent call last):
  File "D:\Bhangaar\.venv\lib\site-packages\django\core\handlers\exception.py", line 47, in inner
    response = get_response(request)
  File "D:\Bhangaar\.venv\lib\site-packages\django\core\handlers\base.py", line 181, in _get_response
    response = wrapped_callback(request, *callback_args, **callback_kwargs)
  File "D:\Bhangaar\.venv\lib\site-packages\django\views\decorators\csrf.py", line 54, in wrapped_view
    return view_func(*args, **kwargs)
  File "D:\Bhangaar\.venv\lib\site-packages\django\views\generic\base.py", line 69, in view
    return self.dispatch(request, *args, **kwargs)
  File "D:\Bhangaar\.venv\lib\site-packages\rest_framework\views.py", line 509, in dispatch
    response = self.handle_exception(exc)
  File "D:\Bhangaar\.venv\lib\site-packages\rest_framework\views.py", line 469, in handle_exception
    self.raise_uncaught_exception(exc)
  File "D:\Bhangaar\.venv\lib\site-packages\rest_framework\views.py", line 480, in raise_uncaught_exception
    raise exc
  File "D:\Bhangaar\.venv\lib\site-packages\rest_framework\views.py", line 506, in dispatch
    response = handler(request, *args, **kwargs)
  File "D:\Bhangaar\EventsMarketPlace\events\views.py", line 41, in get
    events = Event.objects.in_datetime_range(starts_at, ends_at)
  File "D:\Bhangaar\.venv\lib\site-packages\django\db\models\manager.py", line 85, in manager_method
    return getattr(self.get_queryset(), name)(*args, **kwargs)
  File "D:\Bhangaar\EventsMarketPlace\events\models.py", line 13, in in_datetime_range
    return self.filter(
  File "D:\Bhangaar\.venv\lib\site-packages\django\db\models\query.py", line 974, in filter
    return self._filter_or_exclude(False, args, kwargs)
  File "D:\Bhangaar\.venv\lib\site-packages\django\db\models\query.py", line 992, in _filter_or_exclude
    clone._filter_or_exclude_inplace(negate, args, kwargs)
  File "D:\Bhangaar\.venv\lib\site-packages\django\db\models\query.py", line 999, in _filter_or_exclude_inplace
    self._query.add_q(Q(*args, **kwargs))
  File "D:\Bhangaar\.venv\lib\site-packages\django\db\models\sql\query.py", line 1375, in add_q
    clause, _ = self._add_q(q_object, self.used_aliases)
  File "D:\Bhangaar\.venv\lib\site-packages\django\db\models\sql\query.py", line 1396, in _add_q
    child_clause, needed_inner = self.build_filter(
  File "D:\Bhangaar\.venv\lib\site-packages\django\db\models\sql\query.py", line 1252, in build_filter
    return self._add_q(
  File "D:\Bhangaar\.venv\lib\site-packages\django\db\models\sql\query.py", line 1396, in _add_q
    child_clause, needed_inner = self.build_filter(
  File "D:\Bhangaar\.venv\lib\site-packages\django\db\models\sql\query.py", line 1329, in build_filter
    condition = self.build_lookup(lookups, col, value)
  File "D:\Bhangaar\.venv\lib\site-packages\django\db\models\sql\query.py", line 1180, in build_lookup
    lookup = lookup_class(lhs, rhs)
  File "D:\Bhangaar\.venv\lib\site-packages\django\db\models\lookups.py", line 22, in __init__
    self.rhs = self.get_prep_lookup()
  File "D:\Bhangaar\.venv\lib\site-packages\django\db\models\lookups.py", line 79, in get_prep_lookup
    return self.lhs.output_field.get_prep_value(self.rhs)
  File "D:\Bhangaar\.venv\lib\site-packages\django\db\models\fields\__init__.py", line 1399, in get_prep_value
    value = super().get_prep_value(value)
  File "D:\Bhangaar\.venv\lib\site-packages\django\db\models\fields\__init__.py", line 1288, in get_prep_value
    return self.to_python(value)
  File "D:\Bhangaar\.venv\lib\site-packages\django\db\models\fields\__init__.py", line 1364, in to_python
    raise exceptions.ValidationError(
django.core.exceptions.ValidationError: ['“2021-06-31T21:00:00Z” value has the correct format (YYYY-MM-DD HH:MM[:ss[.uuuuuu]][TZ]) but it is an invalid date/time.']
[2024-06-15 02:43:41] ERROR [django.request:225] Internal Server Error: /api/events/
Traceback (most recent call last):
  File "D:\Bhangaar\.venv\lib\site-packages\django\utils\dateparse.py", line 116, in parse_datetime
    return datetime.datetime.fromisoformat(value)
ValueError: Invalid isoformat string: '2021-06-30T24:00:00Z'

During handling of the above exception, another exception occurred:

Traceback (most recent call last):
  File "D:\Bhangaar\.venv\lib\site-packages\django\db\models\fields\__init__.py", line 1360, in to_python
    parsed = parse_datetime(value)
  File "D:\Bhangaar\.venv\lib\site-packages\django\utils\dateparse.py", line 131, in parse_datetime
    return datetime.datetime(**kw, tzinfo=tzinfo)
ValueError: hour must be in 0..23

During handling of the above exception, another exception occurred:

Traceback (most recent call last):
  File "D:\Bhangaar\.venv\lib\site-packages\django\core\handlers\exception.py", line 47, in inner
    response = get_response(request)
  File "D:\Bhangaar\.venv\lib\site-packages\django\core\handlers\base.py", line 181, in _get_response
    response = wrapped_callback(request, *callback_args, **callback_kwargs)
  File "D:\Bhangaar\.venv\lib\site-packages\django\views\decorators\csrf.py", line 54, in wrapped_view
    return view_func(*args, **kwargs)
  File "D:\Bhangaar\.venv\lib\site-packages\django\views\generic\base.py", line 69, in view
    return self.dispatch(request, *args, **kwargs)
  File "D:\Bhangaar\.venv\lib\site-packages\rest_framework\views.py", line 509, in dispatch
    response = self.handle_exception(exc)
  File "D:\Bhangaar\.venv\lib\site-packages\rest_framework\views.py", line 469, in handle_exception
    self.raise_uncaught_exception(exc)
  File "D:\Bhangaar\.venv\lib\site-packages\rest_framework\views.py", line 480, in raise_uncaught_exception
    raise exc
  File "D:\Bhangaar\.venv\lib\site-packages\rest_framework\views.py", line 506, in dispatch
    response = handler(request, *args, **kwargs)
  File "D:\Bhangaar\EventsMarketPlace\events\views.py", line 41, in get
    events = Event.objects.in_datetime_range(starts_at, ends_at)
  File "D:\Bhangaar\.venv\lib\site-packages\django\db\models\manager.py", line 85, in manager_method
    return getattr(self.get_queryset(), name)(*args, **kwargs)
  File "D:\Bhangaar\EventsMarketPlace\events\models.py", line 13, in in_datetime_range
    return self.filter(
  File "D:\Bhangaar\.venv\lib\site-packages\django\db\models\query.py", line 974, in filter
    return self._filter_or_exclude(False, args, kwargs)
  File "D:\Bhangaar\.venv\lib\site-packages\django\db\models\query.py", line 992, in _filter_or_exclude
    clone._filter_or_exclude_inplace(negate, args, kwargs)
  File "D:\Bhangaar\.venv\lib\site-packages\django\db\models\query.py", line 999, in _filter_or_exclude_inplace
    self._query.add_q(Q(*args, **kwargs))
  File "D:\Bhangaar\.venv\lib\site-packages\django\db\models\sql\query.py", line 1375, in add_q
    clause, _ = self._add_q(q_object, self.used_aliases)
  File "D:\Bhangaar\.venv\lib\site-packages\django\db\models\sql\query.py", line 1396, in _add_q
    child_clause, needed_inner = self.build_filter(
  File "D:\Bhangaar\.venv\lib\site-packages\django\db\models\sql\query.py", line 1252, in build_filter
    return self._add_q(
  File "D:\Bhangaar\.venv\lib\site-packages\django\db\models\sql\query.py", line 1396, in _add_q
    child_clause, needed_inner = self.build_filter(
  File "D:\Bhangaar\.venv\lib\site-packages\django\db\models\sql\query.py", line 1329, in build_filter
    condition = self.build_lookup(lookups, col, value)
  File "D:\Bhangaar\.venv\lib\site-packages\django\db\models\sql\query.py", line 1180, in build_lookup
    lookup = lookup_class(lhs, rhs)
  File "D:\Bhangaar\.venv\lib\site-packages\django\db\models\lookups.py", line 22, in __init__
    self.rhs = self.get_prep_lookup()
  File "D:\Bhangaar\.venv\lib\site-packages\django\db\models\lookups.py", line 79, in get_prep_lookup
    return self.lhs.output_field.get_prep_value(self.rhs)
  File "D:\Bhangaar\.venv\lib\site-packages\django\db\models\fields\__init__.py", line 1399, in get_prep_value
    value = super().get_prep_value(value)
  File "D:\Bhangaar\.venv\lib\site-packages\django\db\models\fields\__init__.py", line 1288, in get_prep_value
    return self.to_python(value)
  File "D:\Bhangaar\.venv\lib\site-packages\django\db\models\fields\__init__.py", line 1364, in to_python
    raise exceptions.ValidationError(
django.core.exceptions.ValidationError: ['“2021-06-30T24:00:00Z” value has the correct format (YYYY-MM-DD HH:MM[:ss[.uuuuuu]][TZ]) but it is an invalid date/time.']
[2024-06-15 02:46:48] ERROR [django.request:225] Internal Server Error: /api/events/
Traceback (most recent call last):
  File "D:\Bhangaar\.venv\lib\site-packages\django\utils\dateparse.py", line 116, in parse_datetime
    return datetime.datetime.fromisoformat(value)
ValueError: Invalid isoformat string: '2021-06-31T20:53:00Z'

During handling of the above exception, another exception occurred:

Traceback (most recent call last):
  File "D:\Bhangaar\.venv\lib\site-packages\django\db\models\fields\__init__.py", line 1360, in to_python
    parsed = parse_datetime(value)
  File "D:\Bhangaar\.venv\lib\site-packages\django\utils\dateparse.py", line 131, in parse_datetime
    return datetime.datetime(**kw, tzinfo=tzinfo)
ValueError: day is out of range for month

During handling of the above exception, another exception occurred:

Traceback (most recent call last):
  File "D:\Bhangaar\.venv\lib\site-packages\django\core\handlers\exception.py", line 47, in inner
    response = get_response(request)
  File "D:\Bhangaar\.venv\lib\site-packages\django\core\handlers\base.py", line 181, in _get_response
    response = wrapped_callback(request, *callback_args, **callback_kwargs)
  File "D:\Bhangaar\.venv\lib\site-packages\django\views\decorators\csrf.py", line 54, in wrapped_view
    return view_func(*args, **kwargs)
  File "D:\Bhangaar\.venv\lib\site-packages\django\views\generic\base.py", line 69, in view
    return self.dispatch(request, *args, **kwargs)
  File "D:\Bhangaar\.venv\lib\site-packages\rest_framework\views.py", line 509, in dispatch
    response = self.handle_exception(exc)
  File "D:\Bhangaar\.venv\lib\site-packages\rest_framework\views.py", line 469, in handle_exception
    self.raise_uncaught_exception(exc)
  File "D:\Bhangaar\.venv\lib\site-packages\rest_framework\views.py", line 480, in raise_uncaught_exception
    raise exc
  File "D:\Bhangaar\.venv\lib\site-packages\rest_framework\views.py", line 506, in dispatch
    response = handler(request, *args, **kwargs)
  File "D:\Bhangaar\EventsMarketPlace\events\views.py", line 42, in get
    events = Event.objects.in_datetime_range(starts_at, ends_at)
  File "D:\Bhangaar\.venv\lib\site-packages\django\db\models\manager.py", line 85, in manager_method
    return getattr(self.get_queryset(), name)(*args, **kwargs)
  File "D:\Bhangaar\EventsMarketPlace\events\models.py", line 13, in in_datetime_range
    return self.filter(
  File "D:\Bhangaar\.venv\lib\site-packages\django\db\models\query.py", line 974, in filter
    return self._filter_or_exclude(False, args, kwargs)
  File "D:\Bhangaar\.venv\lib\site-packages\django\db\models\query.py", line 992, in _filter_or_exclude
    clone._filter_or_exclude_inplace(negate, args, kwargs)
  File "D:\Bhangaar\.venv\lib\site-packages\django\db\models\query.py", line 999, in _filter_or_exclude_inplace
    self._query.add_q(Q(*args, **kwargs))
  File "D:\Bhangaar\.venv\lib\site-packages\django\db\models\sql\query.py", line 1375, in add_q
    clause, _ = self._add_q(q_object, self.used_aliases)
  File "D:\Bhangaar\.venv\lib\site-packages\django\db\models\sql\query.py", line 1396, in _add_q
    child_clause, needed_inner = self.build_filter(
  File "D:\Bhangaar\.venv\lib\site-packages\django\db\models\sql\query.py", line 1252, in build_filter
    return self._add_q(
  File "D:\Bhangaar\.venv\lib\site-packages\django\db\models\sql\query.py", line 1396, in _add_q
    child_clause, needed_inner = self.build_filter(
  File "D:\Bhangaar\.venv\lib\site-packages\django\db\models\sql\query.py", line 1329, in build_filter
    condition = self.build_lookup(lookups, col, value)
  File "D:\Bhangaar\.venv\lib\site-packages\django\db\models\sql\query.py", line 1180, in build_lookup
    lookup = lookup_class(lhs, rhs)
  File "D:\Bhangaar\.venv\lib\site-packages\django\db\models\lookups.py", line 22, in __init__
    self.rhs = self.get_prep_lookup()
  File "D:\Bhangaar\.venv\lib\site-packages\django\db\models\lookups.py", line 79, in get_prep_lookup
    return self.lhs.output_field.get_prep_value(self.rhs)
  File "D:\Bhangaar\.venv\lib\site-packages\django\db\models\fields\__init__.py", line 1399, in get_prep_value
    value = super().get_prep_value(value)
  File "D:\Bhangaar\.venv\lib\site-packages\django\db\models\fields\__init__.py", line 1288, in get_prep_value
    return self.to_python(value)
  File "D:\Bhangaar\.venv\lib\site-packages\django\db\models\fields\__init__.py", line 1364, in to_python
    raise exceptions.ValidationError(
django.core.exceptions.ValidationError: ['“2021-06-31T20:53:00Z” value has the correct format (YYYY-MM-DD HH:MM[:ss[.uuuuuu]][TZ]) but it is an invalid date/time.']
[2024-06-15 02:59:55] ERROR [django.request:225] Internal Server Error: /admin/events/event/add/
Traceback (most recent call last):
  File "D:\Bhangaar\.venv\lib\site-packages\django\core\handlers\exception.py", line 47, in inner
    response = get_response(request)
  File "D:\Bhangaar\.venv\lib\site-packages\django\core\handlers\base.py", line 181, in _get_response
    response = wrapped_callback(request, *callback_args, **callback_kwargs)
  File "D:\Bhangaar\.venv\lib\site-packages\django\contrib\admin\options.py", line 622, in wrapper
    return self.admin_site.admin_view(view)(*args, **kwargs)
  File "D:\Bhangaar\.venv\lib\site-packages\django\utils\decorators.py", line 130, in _wrapped_view
    response = view_func(request, *args, **kwargs)
  File "D:\Bhangaar\.venv\lib\site-packages\django\views\decorators\cache.py", line 56, in _wrapped_view_func
    response = view_func(request, *args, **kwargs)
  File "D:\Bhangaar\.venv\lib\site-packages\django\contrib\admin\sites.py", line 236, in inner
    return view(request, *args, **kwargs)
  File "D:\Bhangaar\.venv\lib\site-packages\django\contrib\admin\options.py", line 1670, in add_view
    return self.changeform_view(request, None, form_url, extra_context)
  File "D:\Bhangaar\.venv\lib\site-packages\django\utils\decorators.py", line 43, in _wrapper
    return bound_method(*args, **kwargs)
  File "D:\Bhangaar\.venv\lib\site-packages\django\utils\decorators.py", line 130, in _wrapped_view
    response = view_func(request, *args, **kwargs)
  File "D:\Bhangaar\.venv\lib\site-packages\django\contrib\admin\options.py", line 1549, in changeform_view
    return self._changeform_view(request, object_id, form_url, extra_context)
  File "D:\Bhangaar\.venv\lib\site-packages\django\contrib\admin\options.py", line 1599, in _changeform_view
    self.save_model(request, new_object, form, not add)
  File "D:\Bhangaar\.venv\lib\site-packages\django\contrib\admin\options.py", line 1108, in save_model
    obj.save()
  File "D:\Bhangaar\EventsMarketPlace\events\models.py", line 48, in save
    super(Event, self).save(*args, **kwargs)
  File "D:\Bhangaar\.venv\lib\site-packages\django\db\models\base.py", line 743, in save
    self.save_base(using=using, force_insert=force_insert,
  File "D:\Bhangaar\.venv\lib\site-packages\django\db\models\base.py", line 780, in save_base
    updated = self._save_table(
  File "D:\Bhangaar\.venv\lib\site-packages\django\db\models\base.py", line 885, in _save_table
    results = self._do_insert(cls._base_manager, using, fields, returning_fields, raw)
  File "D:\Bhangaar\.venv\lib\site-packages\django\db\models\base.py", line 923, in _do_insert
    return manager._insert(
  File "D:\Bhangaar\.venv\lib\site-packages\django\db\models\manager.py", line 85, in manager_method
    return getattr(self.get_queryset(), name)(*args, **kwargs)
  File "D:\Bhangaar\.venv\lib\site-packages\django\db\models\query.py", line 1301, in _insert
    return query.get_compiler(using=using).execute_sql(returning_fields)
  File "D:\Bhangaar\.venv\lib\site-packages\django\db\models\sql\compiler.py", line 1440, in execute_sql
    for sql, params in self.as_sql():
  File "D:\Bhangaar\.venv\lib\site-packages\django\db\models\sql\compiler.py", line 1382, in as_sql
    value_rows = [
  File "D:\Bhangaar\.venv\lib\site-packages\django\db\models\sql\compiler.py", line 1383, in <listcomp>
    [self.prepare_value(field, self.pre_save_val(field, obj)) for field in fields]
  File "D:\Bhangaar\.venv\lib\site-packages\django\db\models\sql\compiler.py", line 1383, in <listcomp>
    [self.prepare_value(field, self.pre_save_val(field, obj)) for field in fields]
  File "D:\Bhangaar\.venv\lib\site-packages\django\db\models\sql\compiler.py", line 1324, in prepare_value
    value = field.get_db_prep_save(value, connection=self.connection)
  File "D:\Bhangaar\.venv\lib\site-packages\django\db\models\fields\__init__.py", line 839, in get_db_prep_save
    return self.get_db_prep_value(value, connection=connection, prepared=False)
  File "D:\Bhangaar\.venv\lib\site-packages\django\db\models\fields\__init__.py", line 2272, in get_db_prep_value
    return connection.ops.adapt_timefield_value(value)
  File "D:\Bhangaar\.venv\lib\site-packages\django\db\backends\sqlite3\operations.py", line 273, in adapt_timefield_value
    raise ValueError("SQLite backend does not support timezone-aware times.")
ValueError: SQLite backend does not support timezone-aware times.
